[2025-10-23T04:50:20.706+0000] {local_task_job_runner.py:123} INFO - ::group::Pre task execution logs
[2025-10-23T04:50:20.738+0000] {taskinstance.py:2614} INFO - Dependencies all met for dep_context=non-requeueable deps ti=<TaskInstance: Fraud_detection_training.validate_enviroment manual__2025-10-23T04:50:15.691869+00:00 [queued]>
[2025-10-23T04:50:20.752+0000] {taskinstance.py:2614} INFO - Dependencies all met for dep_context=requeueable deps ti=<TaskInstance: Fraud_detection_training.validate_enviroment manual__2025-10-23T04:50:15.691869+00:00 [queued]>
[2025-10-23T04:50:20.752+0000] {taskinstance.py:2867} INFO - Starting attempt 1 of 1
[2025-10-23T04:50:20.792+0000] {taskinstance.py:2890} INFO - Executing <Task(BashOperator): validate_enviroment> on 2025-10-23 04:50:15.691869+00:00
[2025-10-23T04:50:20.806+0000] {warnings.py:112} WARNING - /home/***/.local/lib/python3.12/site-packages/***/task/task_runner/standard_task_runner.py:70: DeprecationWarning: This process (pid=96) is multi-threaded, use of fork() may lead to deadlocks in the child.
  pid = os.fork()

[2025-10-23T04:50:20.810+0000] {standard_task_runner.py:72} INFO - Started process 97 to run task
[2025-10-23T04:50:20.812+0000] {standard_task_runner.py:104} INFO - Running: ['***', 'tasks', 'run', 'Fraud_detection_training', 'validate_enviroment', 'manual__2025-10-23T04:50:15.691869+00:00', '--job-id', '7', '--raw', '--subdir', 'DAGS_FOLDER/fraud_detection_training_dag.py', '--cfg-path', '/tmp/tmpebkgj9sq']
[2025-10-23T04:50:20.815+0000] {standard_task_runner.py:105} INFO - Job 7: Subtask validate_enviroment
[2025-10-23T04:50:20.904+0000] {task_command.py:467} INFO - Running <TaskInstance: Fraud_detection_training.validate_enviroment manual__2025-10-23T04:50:15.691869+00:00 [running]> on host 661dc816a375
[2025-10-23T04:50:21.088+0000] {taskinstance.py:3134} INFO - Exporting env vars: AIRFLOW_CTX_DAG_OWNER='Rogelio Franco' AIRFLOW_CTX_DAG_ID='Fraud_detection_training' AIRFLOW_CTX_TASK_ID='validate_enviroment' AIRFLOW_CTX_EXECUTION_DATE='2025-10-23T04:50:15.691869+00:00' AIRFLOW_CTX_TRY_NUMBER='1' AIRFLOW_CTX_DAG_RUN_ID='manual__2025-10-23T04:50:15.691869+00:00'
[2025-10-23T04:50:21.091+0000] {taskinstance.py:732} INFO - ::endgroup::
[2025-10-23T04:50:21.179+0000] {subprocess.py:78} INFO - Tmp dir root location: /tmp
[2025-10-23T04:50:21.183+0000] {subprocess.py:88} INFO - Running command: ['/usr/bin/bash', '-c', '\n        echo "Validating enviroment......"\n        test -f /app/config.yaml &&\n        test -f /app/.env &&\n        echo "Enviroment is valid!\n        ']
[2025-10-23T04:50:21.207+0000] {subprocess.py:99} INFO - Output:
[2025-10-23T04:50:21.215+0000] {subprocess.py:106} INFO - Validating enviroment......
[2025-10-23T04:50:21.216+0000] {subprocess.py:106} INFO - /usr/bin/bash: -c: line 5: unexpected EOF while looking for matching `"'
[2025-10-23T04:50:21.218+0000] {subprocess.py:110} INFO - Command exited with return code 2
[2025-10-23T04:50:21.250+0000] {taskinstance.py:3313} ERROR - Task failed with exception
Traceback (most recent call last):
  File "/home/airflow/.local/lib/python3.12/site-packages/airflow/models/taskinstance.py", line 763, in _execute_task
    result = _execute_callable(context=context, **execute_callable_kwargs)
             ^^^^^^^^^^^^^^^^^^^^^^^^^^^^^^^^^^^^^^^^^^^^^^^^^^^^^^^^^^^^^
  File "/home/airflow/.local/lib/python3.12/site-packages/airflow/models/taskinstance.py", line 734, in _execute_callable
    return ExecutionCallableRunner(
           ^^^^^^^^^^^^^^^^^^^^^^^^
  File "/home/airflow/.local/lib/python3.12/site-packages/airflow/utils/operator_helpers.py", line 252, in run
    return self.func(*args, **kwargs)
           ^^^^^^^^^^^^^^^^^^^^^^^^^^
  File "/home/airflow/.local/lib/python3.12/site-packages/airflow/models/baseoperator.py", line 424, in wrapper
    return func(self, *args, **kwargs)
           ^^^^^^^^^^^^^^^^^^^^^^^^^^^
  File "/home/airflow/.local/lib/python3.12/site-packages/airflow/operators/bash.py", line 276, in execute
    raise AirflowException(
airflow.exceptions.AirflowException: Bash command failed. The command returned a non-zero exit code 2.
[2025-10-23T04:50:21.268+0000] {taskinstance.py:1226} INFO - Marking task as FAILED. dag_id=Fraud_detection_training, task_id=validate_enviroment, run_id=manual__2025-10-23T04:50:15.691869+00:00, execution_date=20251023T045015, start_date=20251023T045020, end_date=20251023T045021
[2025-10-23T04:50:21.359+0000] {taskinstance.py:341} INFO - ::group::Post task execution logs
[2025-10-23T04:50:21.360+0000] {standard_task_runner.py:124} ERROR - Failed to execute job 7 for task validate_enviroment (Bash command failed. The command returned a non-zero exit code 2.; 97)
Traceback (most recent call last):
  File "/home/airflow/.local/lib/python3.12/site-packages/airflow/task/task_runner/standard_task_runner.py", line 117, in _start_by_fork
    ret = args.func(args, dag=self.dag)
          ^^^^^^^^^^^^^^^^^^^^^^^^^^^^^
  File "/home/airflow/.local/lib/python3.12/site-packages/airflow/cli/cli_config.py", line 49, in command
    return func(*args, **kwargs)
           ^^^^^^^^^^^^^^^^^^^^^
  File "/home/airflow/.local/lib/python3.12/site-packages/airflow/utils/cli.py", line 116, in wrapper
    return f(*args, **kwargs)
           ^^^^^^^^^^^^^^^^^^
  File "/home/airflow/.local/lib/python3.12/site-packages/airflow/cli/commands/task_command.py", line 483, in task_run
    task_return_code = _run_task_by_selected_method(args, _dag, ti)
                       ^^^^^^^^^^^^^^^^^^^^^^^^^^^^^^^^^^^^^^^^^^^^
  File "/home/airflow/.local/lib/python3.12/site-packages/airflow/cli/commands/task_command.py", line 256, in _run_task_by_selected_method
    return _run_raw_task(args, ti)
           ^^^^^^^^^^^^^^^^^^^^^^^
  File "/home/airflow/.local/lib/python3.12/site-packages/airflow/cli/commands/task_command.py", line 341, in _run_raw_task
    return ti._run_raw_task(
           ^^^^^^^^^^^^^^^^^
  File "/home/airflow/.local/lib/python3.12/site-packages/airflow/utils/session.py", line 97, in wrapper
    return func(*args, session=session, **kwargs)
           ^^^^^^^^^^^^^^^^^^^^^^^^^^^^^^^^^^^^^^
  File "/home/airflow/.local/lib/python3.12/site-packages/airflow/models/taskinstance.py", line 3006, in _run_raw_task
    return _run_raw_task(
           ^^^^^^^^^^^^^^
  File "/home/airflow/.local/lib/python3.12/site-packages/airflow/models/taskinstance.py", line 274, in _run_raw_task
    TaskInstance._execute_task_with_callbacks(
  File "/home/airflow/.local/lib/python3.12/site-packages/airflow/models/taskinstance.py", line 3161, in _execute_task_with_callbacks
    result = self._execute_task(context, task_orig)
             ^^^^^^^^^^^^^^^^^^^^^^^^^^^^^^^^^^^^^^
  File "/home/airflow/.local/lib/python3.12/site-packages/airflow/models/taskinstance.py", line 3185, in _execute_task
    return _execute_task(self, context, task_orig)
           ^^^^^^^^^^^^^^^^^^^^^^^^^^^^^^^^^^^^^^^
  File "/home/airflow/.local/lib/python3.12/site-packages/airflow/models/taskinstance.py", line 763, in _execute_task
    result = _execute_callable(context=context, **execute_callable_kwargs)
             ^^^^^^^^^^^^^^^^^^^^^^^^^^^^^^^^^^^^^^^^^^^^^^^^^^^^^^^^^^^^^
  File "/home/airflow/.local/lib/python3.12/site-packages/airflow/models/taskinstance.py", line 734, in _execute_callable
    return ExecutionCallableRunner(
           ^^^^^^^^^^^^^^^^^^^^^^^^
  File "/home/airflow/.local/lib/python3.12/site-packages/airflow/utils/operator_helpers.py", line 252, in run
    return self.func(*args, **kwargs)
           ^^^^^^^^^^^^^^^^^^^^^^^^^^
  File "/home/airflow/.local/lib/python3.12/site-packages/airflow/models/baseoperator.py", line 424, in wrapper
    return func(self, *args, **kwargs)
           ^^^^^^^^^^^^^^^^^^^^^^^^^^^
  File "/home/airflow/.local/lib/python3.12/site-packages/airflow/operators/bash.py", line 276, in execute
    raise AirflowException(
airflow.exceptions.AirflowException: Bash command failed. The command returned a non-zero exit code 2.
[2025-10-23T04:50:21.393+0000] {local_task_job_runner.py:266} INFO - Task exited with return code 1
[2025-10-23T04:50:21.459+0000] {taskinstance.py:3901} INFO - 0 downstream tasks scheduled from follow-on schedule check
[2025-10-23T04:50:21.468+0000] {local_task_job_runner.py:245} INFO - ::endgroup::
